MusicNotesTrainer/bin/R.txt
int array hofentries_array 0x7f090000
int attr adSize 0x7f010000
int attr adSizes 0x7f010001
int attr adUnitId 0x7f010002
int attr appTheme 0x7f010016
int attr buyButtonAppearance 0x7f01001d
int attr buyButtonHeight 0x7f01001a
int attr buyButtonText 0x7f01001c
int attr buyButtonWidth 0x7f01001b
int attr cameraBearing 0x7f010007
int attr cameraTargetLat 0x7f010008
int attr cameraTargetLng 0x7f010009
int attr cameraTilt 0x7f01000a
int attr cameraZoom 0x7f01000b
int attr circleCrop 0x7f010005
int attr environment 0x7f010017
int attr fragmentMode 0x7f010019
int attr fragmentStyle 0x7f010018
int attr imageAspectRatio 0x7f010004
int attr imageAspectRatioAdjust 0x7f010003
int attr liteMode 0x7f01000c
int attr mapType 0x7f010006
int attr maskedWalletDetailsBackground 0x7f010020
int attr maskedWalletDetailsButtonBackground 0x7f010022
int attr maskedWalletDetailsButtonTextAppearance 0x7f010021
int attr maskedWalletDetailsHeaderTextAppearance 0x7f01001f
int attr maskedWalletDetailsLogoImageType 0x7f010024
int attr maskedWalletDetailsLogoTextColor 0x7f010023
int attr maskedWalletDetailsTextAppearance 0x7f01001e
int attr uiCompass 0x7f01000d
int attr uiMapToolbar 0x7f010015
int attr uiRotateGestures 0x7f01000e
int attr uiScrollGestures 0x7f01000f
int attr uiTiltGestures 0x7f010010
int attr uiZoomControls 0x7f010011
int attr uiZoomGestures 0x7f010012
int attr useViewLifecycle 0x7f010013
int attr zOrderOnTop 0x7f010014
int color common_action_bar_splitter 0x7f070009
int color common_signin_btn_dark_text_default 0x7f070000
int color common_signin_btn_dark_text_disabled 0x7f070002
int color common_signin_btn_dark_text_focused 0x7f070003
int color common_signin_btn_dark_text_pressed 0x7f070001
int color common_signin_btn_default_background 0x7f070008
int color common_signin_btn_light_text_default 0x7f070004
int color common_signin_btn_light_text_disabled 0x7f070006
int color common_signin_btn_light_text_focused 0x7f070007
int color common_signin_btn_light_text_pressed 0x7f070005
int color common_signin_btn_text_dark 0x7f070018
int color common_signin_btn_text_light 0x7f070019
int color opaque_red 0x7f070017
int color wallet_bright_foreground_disabled_holo_light 0x7f07000f
int color wallet_bright_foreground_holo_dark 0x7f07000a
int color wallet_bright_foreground_holo_light 0x7f070010
int color wallet_dim_foreground_disabled_holo_dark 0x7f07000c
int color wallet_dim_foreground_holo_dark 0x7f07000b
int color wallet_dim_foreground_inverse_disabled_holo_dark 0x7f07000e
int color wallet_dim_foreground_inverse_holo_dark 0x7f07000d
int color wallet_highlighted_text_holo_dark 0x7f070014
int color wallet_highlighted_text_holo_light 0x7f070013
int color wallet_hint_foreground_holo_dark 0x7f070012
int color wallet_hint_foreground_holo_light 0x7f070011
int color wallet_holo_blue_light 0x7f070015
int color wallet_link_text_light 0x7f070016
int color wallet_primary_text_holo_light 0x7f07001a
int color wallet_secondary_text_holo_dark 0x7f07001b
int drawable background 0x7f020000
int drawable background_game 0x7f020001
int drawable background_hof 0x7f020002
int drawable background_main 0x7f020003
int drawable background_settings 0x7f020004
int drawable button 0x7f020005
int drawable common_full_open_on_phone 0x7f020006
int drawable common_ic_googleplayservices 0x7f020007
int drawable common_signin_btn_icon_dark 0x7f020008
int drawable common_signin_btn_icon_disabled_dark 0x7f020009
int drawable common_signin_btn_icon_disabled_focus_dark 0x7f02000a
int drawable common_signin_btn_icon_disabled_focus_light 0x7f02000b
int drawable common_signin_btn_icon_disabled_light 0x7f02000c
int drawable common_signin_btn_icon_focus_dark 0x7f02000d
int drawable common_signin_btn_icon_focus_light 0x7f02000e
int drawable common_signin_btn_icon_light 0x7f02000f
int drawable common_signin_btn_icon_normal_dark 0x7f020010
int drawable common_signin_btn_icon_normal_light 0x7f020011
int drawable common_signin_btn_icon_pressed_dark 0x7f020012
int drawable common_signin_btn_icon_pressed_light 0x7f020013
int drawable common_signin_btn_text_dark 0x7f020014
int drawable common_signin_btn_text_disabled_dark 0x7f020015
int drawable common_signin_btn_text_disabled_focus_dark 0x7f020016
int drawable common_signin_btn_text_disabled_focus_light 0x7f020017
int drawable common_signin_btn_text_disabled_light 0x7f020018
int drawable common_signin_btn_text_focus_dark 0x7f020019
int drawable common_signin_btn_text_focus_light 0x7f02001a
int drawable common_signin_btn_text_light 0x7f02001b
int drawable common_signin_btn_text_normal_dark 0x7f02001c
int drawable common_signin_btn_text_normal_light 0x7f02001d
int drawable common_signin_btn_text_pressed_dark 0x7f02001e
int drawable common_signin_btn_text_pressed_light 0x7f02001f
int drawable custom_button 0x7f020020
int drawable custom_button_green 0x7f020021
int drawable custom_button_red 0x7f020022
int drawable dialog 0x7f020023
int drawable don_1 0x7f020024
int drawable don_2 0x7f020025
int drawable fa_1 0x7f020026
int drawable fa_2 0x7f020027
int drawable ic_plusone_medium_off_client 0x7f020028
int drawable ic_plusone_small_off_client 0x7f020029
int drawable ic_plusone_standard_off_client 0x7f02002a
int drawable ic_plusone_tall_off_client 0x7f02002b
int drawable la_0 0x7f02002c
int drawable la_1 0x7f02002d
int drawable la_2 0x7f02002e
int drawable menu 0x7f02002f
int drawable menu_hof 0x7f020030
int drawable menu_omt 0x7f020031
int drawable menu_quit 0x7f020032
int drawable menu_settings 0x7f020033
int drawable menu_training 0x7f020034
int drawable mi_1 0x7f020035
int drawable mi_2 0x7f020036
int drawable music 0x7f020037
int drawable music1 0x7f020038
int drawable powered_by_google_dark 0x7f020039
int drawable powered_by_google_light 0x7f02003a
int drawable re_1 0x7f02003b
int drawable re_2 0x7f02003c
int drawable score 0x7f02003d
int drawable si_0 0x7f02003e
int drawable si_1 0x7f02003f
int drawable si_2 0x7f020040
int drawable sol_0 0x7f020041
int drawable sol_1 0x7f020042
int drawable sol_2 0x7f020043
int id adViewgame 0x7f0b0025
int id adViewhof 0x7f0b002a
int id adViewmain 0x7f0b0031
int id adjust_height 0x7f0b0000
int id adjust_width 0x7f0b0001
int id book_now 0x7f0b0010
int id buyButton 0x7f0b000c
int id buy_now 0x7f0b0011
int id buy_with_google 0x7f0b0012
int id chrono 0x7f0b0019
int id classic 0x7f0b0014
int id don 0x7f0b0022
int id donate_with_google 0x7f0b0013
int id endgame 0x7f0b0026
int id exithof 0x7f0b002b
int id fa 0x7f0b0023
int id fila0 0x7f0b0018
int id fila1 0x7f0b001a
int id fila2 0x7f0b001c
int id fila3 0x7f0b0020
int id general 0x7f0b0017
int id grayscale 0x7f0b0015
int id hof 0x7f0b0030
int id hoftable 0x7f0b0028
int id hoftitle 0x7f0b0027
int id holo_dark 0x7f0b0007
int id holo_light 0x7f0b0008
int id hybrid 0x7f0b0003
int id imageView1 0x7f0b002d
int id imageView2 0x7f0b002c
int id imgnota 0x7f0b001b
int id la 0x7f0b0024
int id match_parent 0x7f0b000e
int id menu_1mintest 0x7f0b0047
int id menu_Quit 0x7f0b004b
int id menu_hof 0x7f0b0049
int id menu_settings 0x7f0b004a
int id menu_training 0x7f0b0048
int id mi 0x7f0b001f
int id mintest 0x7f0b002e
int id monochrome 0x7f0b0016
int id none 0x7f0b0002
int id normal 0x7f0b0004
int id production 0x7f0b0009
int id rbbizantine 0x7f0b003a
int id rbenglish 0x7f0b0038
int id rbindian 0x7f0b003c
int id rbjapanese 0x7f0b003b
int id rbno 0x7f0b0046
int id rbnortheneuropean 0x7f0b0039
int id rbseeuropean 0x7f0b0037
int id rbyes 0x7f0b0045
int id re 0x7f0b001d
int id relativeLayout1 0x7f0b0029
int id rginformer 0x7f0b0044
int id rgnotation 0x7f0b0036
int id sandbox 0x7f0b000a
int id satellite 0x7f0b0005
int id selectionDetails 0x7f0b000d
int id separator 0x7f0b003d
int id separator2 0x7f0b0041
int id si 0x7f0b001e
int id sol 0x7f0b0021
int id sphofentries 0x7f0b0040
int id strict_sandbox 0x7f0b000b
int id svsettings 0x7f0b0033
